Workbook

Sheet Slip April
A3: nms (Thailand) Co.,Ltd.
A4: Company : Canadian ( Phase 3)
A5: Cut Off : 26 January 2024 - 25 Febuary 2025
A6: Billing :
A8: nms (Thailand) Co.,Ltd.
A9: Company | B9: : | C9: Canadian ( Phase 3)
A10: Cut Off | B10: : | C10: 26 January 2024 - 25 Febuary 2025
A11: Billing | B11: :
A12: Sub-Con Salary | B12: : | C12: 05 March 2025
A13: Month | B13: : | C13: Febuary 2025
A14: Branch | B14: : | C14: Amata City
B15: 1 | C15: 2 | D15: 3 | E15: 4 | F15: 5 | G15: 6 | H15: 7 | I15: 8 | J15: 9 | K15: 10 | L15: 11 | M15: 12 | N15: 13 | O15: 14 | P15: 15 | Q15: 16 | R15: 17 | S15: 18 | T15: 19 | U15: 20 | V15: 21 | W15: 22 | X15: 23 | Y15: 24 | Z15: 25 | AA15: 26 | AB15: 27 | AC15: 28 | AD15: 29 | AE15: 30 | AF15: 31 | AG15: 32 | AH15: 33 | AI15: 34 | AJ15: 35 | AK15: 36 | AL15: 37 | AM15: 38 | AN15: 39 | AO15: 40 | AP15: 41 | AQ15: 42 | AR15: 43 | AS15: 44 | AT15: 45 | AU15: 46 | AV15: 47 | AW15: 48 | AX15: 49 | AY15: 50 | AZ15: 51 | BA15: 52 | BB15: 53 | BC15: 54 | BD15: 55 | BE15: 56 | BF15: 57 | BG15: 58 | BH15: 59 | BI15: 60 | BJ15: 61 | BK15: 62 | BL15: 63 | BM15: 64 | BN15: 65 | BO15: 66 | BP15: 67 | BQ15: 68 | BR15: 69 | BS15: 70 | BT15: 71 | BU15: 72 | BV15: 73 | BW15: 74 | BX15: 75 | BY15: 76 | BZ15: 77 | CA15: 78 | CB15: 79 | CC15: 80 | CD15: 81 | CE15: 82 | CF15: 83 | CG15: 84 | CH15: 85 | CI15: 86 | CJ15: 87 | CK15: 88 | CL15: 89 | CM15: 90 | CN15: 91 | CO15: 92 | CP15: 93 | CQ15: 94 | CR15: 95 | CS15: 96 | CT15: 97 | CU15: 98 | CV15: 99 | CW15: 100 | CX15: 101 | CY15: 102 | CZ15: 103 | DA15: 104 | DB15: 105 | DC15: 106 | DD15: 107 | DE15: 108 | DF15: 109 | DG15: 110 | DH15: 111 | DI15: 112 | DJ15: 113 | DK15: 114 | DL15: 115 | DM15: 116 | DN15: 117 | DO15: 118 | DP15: 119 | DQ15: 120 | DR15: 121 | DS15: 122 | DT15: 123 | DU15: 124 | DV15: 125 | DW15: 126 | DX15: 127 | DY15: 128 | DZ15: 129 | EA15: 130 | EB15: 131 | EC15: 132 | ED15: 133 | EE15: 134 | EF15: 135 | EG15: 136 | EH15: 137 | EI15: 138 | EJ15: 139 | EK15: 140 | EL15: 141 | EM15: 142 | EN15: 143 | EO15: 144 | EP15: 145
A16: NO | B16: เลขรหัส / ID | C16: ชื่อ-สกุล / Name | D16: ID Card | E16: แผนก / Department | F16: ตำแหน่ง / Position | G16: วันเริ่มทำงาน / Start Working | H16: ทำงานวันสุดท้าย / Last Working | I16: เงินเดือน / Salary | J16: Working Days | L16: ชั่วโมงการทำงาน / Working hours | P16: ค่าแรง 75% | R16: ค่าแรง 80% | T16: ค่าแรง 85% | V16: Holiday | X16: Leave | AE16: Paid Leave | AF16: Paid Salary | AG16: Allowance | CG16: จำนวนชั่วโมงทำงานล่วงเวลา / Total Overtime | CH16: สวัสดิการรวมทั้งหมด / Total Allowance | CI16: รายการปรับ / Adjust | CJ16: รายการหัก /Deduct | CK16: โบนัส / Bonus | CL16: รายรับทั้งหมด / Total Income | CT16: Deduct | CZ16: ไม่มีรายการหัก / Non-Deduct | DA16: รวมทั้งหมด / Total Payment | DB16: รายได้สะสมประจำปี 2568 | DO16: หักลดหย่อน | DP16: TAX | DQ16: ประกันสังคมสะสม ประจำปี 2568 | ED16: สงเคราะห์กองทุนลูกจ้าง 2568
J17: Day | K17: Baht | L17: Day | M17: Baht | N17: Day | O17: วันหยุดประเพณี /Tradition | P17: Day | Q17: Baht | R17: Day | S17: Baht | T17: Day | U17: Baht | V17: Hours | W17: Baht | X17: SL | Y17: SLC | Z17: BL | AA17: BLC | AB17: AL | AC17: AB | AD17: ML | AG17: ค่าอาหาร / Meal Allowance | AH17: ค่าอาหารวันหยุด / Holiday Meal Allowance | AI17: ค่าอาหารล่วงเวลา / OT Meal Allowance | AJ17: ค่ากะดึก / Night Shift | AK17: ค่าอาหารกะดึก / Night Shift Meal Allowance | AL17: ค่ากะเช้า / Day Shift | AM17: ค่าเดินทาง / Transportation | AN17: ค่าเช่าบ้าน / Rental Allowance | AO17: ค่าทักษะ / Skill-Based | AP17: ค่าครองชีพ / Cost of Living Allowance | AQ17: ค่าลักษณะงาน / Job Discription | AR17: ค่าตำแหน่ง / Position Allowance | AS17: ค่าตรวจพบงานเสีย / Quality Award | AT17: ค่าความเสี่ยง / Risk Allowance | AU17: ค่าตัวชี้วันประสิทธิภาพ / KPI | AV17: ค่าเดินทางออกต่างจังหวัด / Off-Site Travel Expenses (150) | AW17: ค่าเดินทางออกต่างจังหวัด / Off-Site Travel Expenses (180) | AX17: ค่าจอดรถ / Parking Fee | AY17: เบี้ยขยัน / Diligence | AZ17: เบี้ยขยันพิเศษ / Special Diligence | BA17: เงินพิเศษสำหรับพนักงาน / Extra Money For Emplyoees | BB17: ค่าทำงานต่างพื้นที่ / Fees for work in different area | BC17: เบี้ยเลี้ยงออกนอกสถานที่/ Outside Allowance | BD17: สิทธิประโยชน์พิเศษ / Special Benefit | BE17: ค่าคอมมิชชั่น / Commission | BF17: อินเซนทีฟ / Incentive | BG17: ค่าชดเชยพิเศษ / Special Allownce | BH17: รางวัลบริการประจำปี / Service Year Award | BI17: คืนพักร้อนประจำปี/ Pay Annual Vacation | BJ17: โบนัส / Bonus | BK17: ตกเบิก/ Adjust | BL17: อื่นๆ / Other | BM17: 1.0 X | BO17: 1.3 X | BQ17: 1.5 X | BS17: 1.7 X | BU17: 2.0 X ปกติ | BW17: 2.2 X | BY17: 3.0 X ปกติ | CA17: 2.0 X นักขัตฤกษ์ | CC17: 3.0 X นักขัตฤกษ์ | CE17: 3.2 X | CM17: ภาษีหัก ณ ที่จ่าย/ Tax. | CN17: ประกัน สังคม / SSF | CO17: สงเคราะห์กองทุนลูกจ้าง | CP17: กองทุนสำรองเลี้ยงชีพ | CQ17: กยศ. / Student loan (TSLF) | CR17: หักบังคับคดี/ Enforcement | CS17: เงินเบิกล่วงหน้า/Advance | CT17: ชุดยูนิฟอร์ม / Uniform | CU17: คูปอง / Cashless | CV17: รางวัลบริการประจำปี/ Service Year Award | CW17: หยุดงาน,สาย,กลับก่อน / Absent, Late, Leave early | CX17: อปุกรณ์โรงงาน / PPE | CY17: อื่นๆ / Other
X18: Day | Y18: Day | Z18: Day | AA18: Day | AB18: Day | AC18: Day | AD18: Day | BM18: Hours | BN18: Amount | BO18: Hours | BP18: Amount | BQ18: Hours | BR18: Amount | BS18: hours | BT18: Amount | BU18: Hours | BV18: Amount | BW18: Hours | BX18: Amount | BY18: Hours | BZ18: Amount | CA18: Hours | CB18: Amount | CC18: Hours | CD18: Amount | CE18: Hours | CF18: Amount | DB18: ม.ค. | DC18: ก.พ. | DD18: มี.ค. | DE18: เม.ย. | DF18: พ.ค. | DG18: มิ.ย. | DH18: ก.ค. | DI18: ส.ค. | DJ18: ก.ย. | DK18: ต.ค. | DL18: พ.ย. | DM18: ธ.ค. | DN18: รวม | DQ18: ม.ค. | DR18: ก.พ. | DS18: มี.ค. | DT18: เม.ย. | DU18: พ.ค. | DV18: มิ.ย. | DW18: ก.ค. | DX18: ส.ค. | DY18: ก.ย. | DZ18: ต.ค. | EA18: พ.ย. | EB18: ธ.ค. | EC18: รวม | ED18: ม.ค. | EE18: ก.พ. | EF18: มี.ค. | EG18: เม.ย. | EH18: พ.ค. | EI18: มิ.ย. | EJ18: ก.ค. | EK18: ส.ค. | EL18: ก.ย. | EM18: ต.ค. | EN18: พ.ย. | EO18: ธ.ค. | EP18: รวม
A19: 1 | B19: NIP67011 | C19: นางสาวฤทัยรัตน์ บุญสม | D19: 1320501333512 | E19: Wafer Production | F19: Operator | G19: 44701 | I19: 400 | J19: 26 | K19: 10400 | L19: 8 | N19: 2 | Q19: 500 | R19: 5 | V19: 8 | W19: 400 | X19: 0 | Y19: 0 | Z19: 0 | AA19: 0 | AB19: 0 | AC19: 0 | AD19: 0 | AE19: 0 | AF19: 10400 | AG19: 1300 | AH19: 1800 | AI19: 1200 | AJ19: 2900 | AK19: 1800 | AL19: 0 | AM19: 0 | AN19: 500 | AO19: 500 | AP19: 3000 | AQ19: 0 | AR19: 500 | AS19: 1350.04 | BL19: 800 | BU19: 32 | BV19: 3200 | BY19: 12 | BZ19: 1800 | CA19: 0 | CB19: 0 | CE19: 0 | CF19: 0 | CG19: 10850 | CH19: 14650.04 | CI19: 0 | CJ19: 0 | CL19: 35900.04 | CO19: 312 | CT19: 0 | CV19: 0 | CY19: 0 | DA19: 35588.04 | DB19: 24001.48 | DC19: 35900.04 | DN19: 59901.52 | DO19: -30659.24 | DP19: 0 | DQ19: 298 | DR19: 312 | EC19: =SUM(DQ19:EB19) -> 610 | ED19: =CP19 -> 0 | EP19: =SUM(ED19:EO19) -> 0
A20: 2 | B20: NIP67014 | C20: นางสาวสุจิตรา วงค์ศรี | D20: 1439900407436 | E20: Cell Production 3 | F20: Operator | G20: 44732 | I20: 400 | J20: 24 | K20: 9600 | V20: 8 | W20: 400 | X20: 0 | Y20: 0 | Z20: 0 | AA20: 0 | AB20: 8 | AC20: 0 | AD20: 0 | AE20: 400 | AF20: 10400 | AG20: 1300 | AH20: 1750 | AI20: 1125 | AJ20: 800 | AK20: 1750 | AL20: 1750 | AM20: 2473.84 | AN20: 0 | AO20: 0 | AP20: 0 | AQ20: 0 | AR20: 500 | AS20: 0 | BU20: 8 | BV20: 800 | BY20: 3 | BZ20: 450 | CA20: 0 | CB20: 0 | CE20: 0 | CF20: 0 | CG20: 6650 | CH20: 8748.84 | CI20: 0 | CJ20: 0 | CL20: 25798.84 | CO20: 312 | CT20: 0 | CV20: 0 | CX20: 136 | CY20: 0 | DA20: 25350.84 | DB20: 28036.72 | DC20: 25798.84 | DN20: 53835.56 | DO20: -33629.22 | DP20: 0 | DQ20: 235 | DR20: 312 | EC20: =SUM(DQ20:EB20) -> 547 | ED20: =CP20 -> 0 | EP20: =SUM(ED20:EO20) -> 0
A21: 3 | B21: NIP67018 | C21: นางสาวน้ำฝน ชิณวงค์ | D21: 5450701079140 | E21: Cell Production 3 | F21: Operator | G21: 44747 | I21: 400 | J21: 26 | K21: 10400 | V21: 8 | W21: 400 | X21: 0 | Y21: 0 | Z21: 0 | AA21: 0 | AB21: 0 | AC21: 0 | AD21: 0 | AE21: 0 | AF21: 10800 | AG21: 1300 | AH21: 2030 | AI21: 1260 | AJ21: 1100 | AK21: 2030 | AL21: 0 | AM21: 300 | AN21: 0 | AO21: 0 | AP21: 0 | AQ21: 0 | AR21: 500 | AS21: 0 | BU21: 24 | BV21: 2400 | BY21: 9 | BZ21: 1350 | CA21: 0 | CB21: 0 | CE21: 0 | CF21: 0 | CG21: 9375 | CH21: 9320 | CI21: 0 | CJ21: 0 | CL21: 29495 | CO21: 324 | CT21: 0 | CV21: 0 | CY21: 0 | DA21: 29171 | DB21: 31930.17 | DC21: 29495 | DN21: 61425.17 | DO21: -29858.415 | DP21: 0 | DQ21: 247 | DR21: 324 | EC21: =SUM(DQ21:EB21) -> 571 | ED21: =CP21 -> 0 | EP21: =SUM(ED21:EO21) -> 0
A22: 4 | B22: NIP67031 | C22: นางสาวอรรจนันท์ คงหา | D22: 1104300428228 | E22: Module Production 3 | F22: Operator | G22: 44781 | I22: 400 | J22: 21 | K22: 8400 | V22: 8 | W22: 400 | X22: 8 | Y22: 0 | Z22: 0 | AA22: 0 | AB22: 8 | AC22: 0 | AD22: 0 | AE22: 400 | AF22: 9200 | AG22: 1300 | AH22: 1260 | AI22: 800 | AJ22: 400 | AK22: 1260 | AL22: 0 | AM22: 2360 | AN22: 5175 | AO22: 0 | AP22: 0 | AQ22: 0 | AR22: 500 | AS22: 0 | BU22: 0 | BV22: 0 | BY22: 0 | BZ22: 0 | CA22: 0 | CB22: 0 | CE22: 0 | CF22: 0 | CG22: 4500 | CH22: 13055 | CI22: 0 | CJ22: 0 | CL22: 26755 | CO22: 276 | CT22: 0 | CV22: 0 | CY22: 0 | DA22: 26479 | DB22: 30443.59 | DC22: 26755 | DN22: 57198.59 | DO22: -31887.705 | DP22: 0 | DQ22: 211 | DR22: 276 | EC22: =SUM(DQ22:EB22) -> 487 | ED22: =CP22 -> 0 | EP22: =SUM(ED22:EO22) -> 0
A23: 5 | B23: NIP67056 | C23: นางสาวพรมะณี กาบทุม | D23: 1449900486859 | E23: Cell Production 3 | F23: Operator | G23: 44943 | I23: 400 | J23: 25 | K23: 10000 | V23: 8 | W23: 400 | X23: 0 | Y23: 0 | Z23: 0 | AA23: 0 | AB23: 8 | AC23: 0 | AD23: 0 | AE23: 400 | AF23: 10800 | AG23: 1300 | AH23: 1890 | AI23: 1215 | AJ23: 1200 | AK23: 1890 | AL23: 0 | AM23: 940.92 | AN23: 0 | AO23: 0 | AP23: 0 | AQ23: 0 | AR23: 500 | AS23: 0 | BU23: 16 | BV23: 1600 | BY23: 6 | BZ23: 900 | CA23: 0 | CB23: 0 | CE23: 0 | CF23: 0 | CG23: 8125 | CH23: 9735.92 | CI23: 0 | CJ23: 0 | CL23: 28660.92 | CO23: 324 | CT23: 0 | CV23: 0 | CY23: 0 | DA23: 28336.92 | DB23: 28933.72 | DC23: 28660.92 | DN23: 57594.64 | DO23: -31750.68 | DP23: 0 | DQ23: 224 | DR23: 324 | EC23: =SUM(DQ23:EB23) -> 548 | ED23: =CP23 -> 0 | EP23: =SUM(ED23:EO23) -> 0
A24: 6 | B24: NIP67057 | C24: TEST 1 | D24: 1449900486860 | E24: Cell Production 4 | F24: Operator | G24: 44944 | I24: 400 | J24: 25 | K24: 10000 | L24: 20 | N24: 3 | P24: 2 | Q24: 200 | R24: 3 | S24: 150 | T24: 3 | U24: 300 | V24: 8 | W24: 400 | X24: 1 | Y24: 2 | Z24: 3 | AA24: 4 | AB24: 5 | AC24: 6 | AD24: 7 | AE24: 400 | AF24: 10800 | AG24: 1300 | AH24: 1890 | AI24: 1215 | AJ24: 1200 | AK24: 1890 | AL24: 1000 | AM24: 940.92 | AN24: 1000 | AO24: 1000 | AP24: 1000 | AQ24: 2000 | AR24: 500 | AS24: 1 | AT24: 2 | AU24: 3 | AV24: 4 | AW24: 5 | AX24: 6 | AY24: 7 | AZ24: 8 | BA24: 9 | BB24: 10 | BC24: 11 | BD24: 12 | BE24: 13 | BF24: 14 | BG24: 15 | BH24: 16 | BI24: 17 | BJ24: 18 | BK24: 19 | BL24: 20 | BM24: 1 | BN24: 100 | BO24: 1 | BP24: 100 | BQ24: 1 | BR24: 100 | BS24: 1 | BT24: 100 | BU24: 16 | BV24: 1600 | BW24: 1 | BX24: 100 | BY24: 6 | BZ24: 900 | CA24: 1 | CB24: 100 | CC24: 1 | CD24: 100 | CE24: 1 | CF24: 100 | CG24: 8125 | CH24: 9735.92 | CI24: 0 | CJ24: 0 | CL24: 28660.92 | CM24: 1 | CN24: 2 | CO24: 324 | CP24: 3 | CQ24: 4 | CR24: 5 | CS24: 6 | CT24: 7 | CU24: 8 | CV24: 9 | CW24: 10 | CX24: 11 | CY24: 12 | CZ24: =SUM(CM24:CY24) -> 402 | DA24: =CL24-CZ24 -> 28258.92 | DB24: 28933.72 | DC24: 28660.92 | DN24: 57594.64 | DO24: -31750.68 | DP24: 0 | DQ24: 224 | DR24: 324 | EC24: =SUM(DQ24:EB24) -> 548 | ED24: =CP24 -> 3 | EP24: =SUM(ED24:EO24) -> 3
A25: 7 | B25: NIP67058 | C25: TEST 2 | D25: 1449900486861 | E25: Cell Production 5 | F25: Operator | G25: 44945 | I25: 400 | J25: 25 | K25: 10000 | V25: 8 | W25: 400 | X25: 0 | Y25: 0 | Z25: 0 | AA25: 0 | AB25: 8 | AC25: 0 | AD25: 0 | AE25: 400 | AF25: 10800 | AG25: 1300 | AH25: 1890 | AI25: 1215 | AJ25: 1200 | AK25: 1890 | AL25: 0 | AM25: 940.92 | AN25: 0 | AO25: 0 | AP25: 0 | AQ25: 0 | AR25: 500 | AS25: 0 | BU25: 16 | BV25: 1600 | BY25: 6 | BZ25: 900 | CA25: 0 | CB25: 0 | CE25: 0 | CF25: 0 | CG25: 8125 | CH25: 9735.92 | CI25: 0 | CJ25: 0 | CL25: 28660.92 | CO25: 324 | CT25: 0 | CV25: 0 | CY25: 0 | CZ25: =SUM(CM25:CY25) -> 324 | DA25: =CL25-CZ25 -> 28336.92 | DB25: 28933.72 | DC25: 28660.92 | DN25: 57594.64 | DO25: -31750.68 | DP25: 0 | DQ25: 224 | DR25: 324 | EC25: =SUM(DQ25:EB25) -> 548 | ED25: =CP25 -> 0 | EP25: =SUM(ED25:EO25) -> 0
A26: 8 | B26: NIP67059 | C26: TEST 3 | D26: 1449900486862 | E26: Cell Production 6 | F26: Operator | G26: 44946 | I26: 400 | J26: 25 | K26: 10000 | V26: 8 | W26: 400 | X26: 0 | Y26: 0 | Z26: 0 | AA26: 0 | AB26: 8 | AC26: 0 | AD26: 0 | AE26: 400 | AF26: 10800 | AG26: 1300 | AH26: 1890 | AI26: 1215 | AJ26: 1200 | AK26: 1890 | AL26: 0 | AM26: 940.92 | AN26: 0 | AO26: 0 | AP26: 0 | AQ26: 0 | AR26: 500 | AS26: 0 | BU26: 16 | BV26: 1600 | BY26: 6 | BZ26: 900 | CA26: 0 | CB26: 0 | CE26: 0 | CF26: 0 | CG26: 8125 | CH26: 9735.92 | CI26: 0 | CJ26: 0 | CL26: 28660.92 | CO26: 324 | CT26: 0 | CV26: 0 | CY26: 0 | CZ26: =SUM(CM26:CY26) -> 324 | DA26: =CL26-CZ26 -> 28336.92 | DB26: 28933.72 | DC26: 28660.92 | DN26: 57594.64 | DO26: -31750.68 | DP26: 0 | DQ26: 224 | DR26: 324 | EC26: =SUM(DQ26:EB26) -> 548 | ED26: =CP26 -> 0 | EP26: =SUM(ED26:EO26) -> 0
A27: 9 | B27: NIP67060 | C27: TEST 4 | D27: 1449900486863 | E27: Cell Production 7 | F27: Operator | G27: 44947 | I27: 400 | J27: 25 | K27: 10000 | V27: 8 | W27: 400 | X27: 0 | Y27: 0 | Z27: 0 | AA27: 0 | AB27: 8 | AC27: 0 | AD27: 0 | AE27: 400 | AF27: 10800 | AG27: 1300 | AH27: 1890 | AI27: 1215 | AJ27: 1200 | AK27: 1890 | AL27: 0 | AM27: 940.92 | AN27: 0 | AO27: 0 | AP27: 0 | AQ27: 0 | AR27: 500 | AS27: 0 | BU27: 16 | BV27: 1600 | BY27: 6 | BZ27: 900 | CA27: 0 | CB27: 0 | CE27: 0 | CF27: 0 | CG27: 8125 | CH27: 9735.92 | CI27: 0 | CJ27: 0 | CL27: 28660.92 | CO27: 324 | CT27: 0 | CV27: 0 | CY27: 0 | CZ27: =SUM(CM27:CY27) -> 324 | DA27: =CL27-CZ27 -> 28336.92 | DB27: 28933.72 | DC27: 28660.92 | DN27: 57594.64 | DO27: -31750.68 | DP27: 0 | DQ27: 224 | DR27: 324 | EC27: =SUM(DQ27:EB27) -> 548 | ED27: =CP27 -> 0 | EP27: =SUM(ED27:EO27) -> 0
A28: 10 | B28: NIP67061 | C28: TEST 5 | D28: 1449900486864 | E28: Cell Production 8 | F28: Operator | G28: 44948 | I28: 400 | J28: 25 | K28: 10000 | V28: 8 | W28: 400 | X28: 0 | Y28: 0 | Z28: 0 | AA28: 0 | AB28: 8 | AC28: 0 | AD28: 0 | AE28: 400 | AF28: 10800 | AG28: 1300 | AH28: 1890 | AI28: 1215 | AJ28: 1200 | AK28: 1890 | AL28: 0 | AM28: 940.92 | AN28: 0 | AO28: 0 | AP28: 0 | AQ28: 0 | AR28: 500 | AS28: 0 | BU28: 16 | BV28: 1600 | BY28: 6 | BZ28: 900 | CA28: 0 | CB28: 0 | CE28: 0 | CF28: 0 | CG28: 8125 | CH28: 9735.92 | CI28: 0 | CJ28: 0 | CL28: 28660.92 | CO28: 324 | CT28: 0 | CV28: 0 | CY28: 0 | CZ28: =SUM(CM28:CY28) -> 324 | DA28: =CL28-CZ28 -> 28336.92 | DB28: 28933.72 | DC28: 28660.92 | DN28: 57594.64 | DO28: -31750.68 | DP28: 0 | DQ28: 224 | DR28: 324 | EC28: =SUM(DQ28:EB28) -> 548 | ED28: =CP28 -> 0 | EP28: =SUM(ED28:EO28) -> 0
A29: 11 | B29: NIP67062 | C29: TEST 6 | D29: 1449900486865 | E29: Cell Production 9 | F29: Operator | G29: 44949 | I29: 400 | J29: 25 | K29: 10000 | V29: 8 | W29: 400 | X29: 0 | Y29: 0 | Z29: 0 | AA29: 0 | AB29: 8 | AC29: 0 | AD29: 0 | AE29: 400 | AF29: 10800 | AG29: 1300 | AH29: 1890 | AI29: 1215 | AJ29: 1200 | AK29: 1890 | AL29: 0 | AM29: 940.92 | AN29: 0 | AO29: 0 | AP29: 0 | AQ29: 0 | AR29: 500 | AS29: 0 | BU29: 16 | BV29: 1600 | BY29: 6 | BZ29: 900 | CA29: 0 | CB29: 0 | CE29: 0 | CF29: 0 | CG29: 8125 | CH29: 9735.92 | CI29: 0 | CJ29: 0 | CL29: 28660.92 | CO29: 324 | CT29: 0 | CV29: 0 | CY29: 0 | CZ29: =SUM(CM29:CY29) -> 324 | DA29: =CL29-CZ29 -> 28336.92 | DB29: 28933.72 | DC29: 28660.92 | DN29: 57594.64 | DO29: -31750.68 | DP29: 0 | DQ29: 224 | DR29: 324 | EC29: =SUM(DQ29:EB29) -> 548 | ED29: =CP29 -> 0 | EP29: =SUM(ED29:EO29) -> 0
A30: 12 | B30: NIP67063 | C30: TEST 7 | D30: 1449900486866 | E30: Cell Production 10 | F30: Operator | G30: 44950 | I30: 400 | J30: 25 | K30: 10000 | V30: 8 | W30: 400 | X30: 0 | Y30: 0 | Z30: 0 | AA30: 0 | AB30: 8 | AC30: 0 | AD30: 0 | AE30: 400 | AF30: 10800 | AG30: 1300 | AH30: 1890 | AI30: 1215 | AJ30: 1200 | AK30: 1890 | AL30: 0 | AM30: 940.92 | AN30: 0 | AO30: 0 | AP30: 0 | AQ30: 0 | AR30: 500 | AS30: 0 | BU30: 16 | BV30: 1600 | BY30: 6 | BZ30: 900 | CA30: 0 | CB30: 0 | CE30: 0 | CF30: 0 | CG30: 8125 | CH30: 9735.92 | CI30: 0 | CJ30: 0 | CL30: 28660.92 | CO30: 324 | CT30: 0 | CV30: 0 | CY30: 0 | CZ30: =SUM(CM30:CY30) -> 324 | DA30: =CL30-CZ30 -> 28336.92 | DB30: 28933.72 | DC30: 28660.92 | DN30: 57594.64 | DO30: -31750.68 | DP30: 0 | DQ30: 224 | DR30: 324 | EC30: =SUM(DQ30:EB30) -> 548 | ED30: =CP30 -> 0 | EP30: =SUM(ED30:EO30) -> 0
A31: 13 | B31: NIP67064 | C31: TEST 8 | D31: 1449900486867 | E31: Cell Production 11 | F31: Operator | G31: 44951 | I31: 400 | J31: 25 | K31: 10000 | V31: 8 | W31: 400 | X31: 0 | Y31: 0 | Z31: 0 | AA31: 0 | AB31: 8 | AC31: 0 | AD31: 0 | AE31: 400 | AF31: 10800 | AG31: 1300 | AH31: 1890 | AI31: 1215 | AJ31: 1200 | AK31: 1890 | AL31: 0 | AM31: 940.92 | AN31: 0 | AO31: 0 | AP31: 0 | AQ31: 0 | AR31: 500 | AS31: 0 | BU31: 16 | BV31: 1600 | BY31: 6 | BZ31: 900 | CA31: 0 | CB31: 0 | CE31: 0 | CF31: 0 | CG31: 8125 | CH31: 9735.92 | CI31: 0 | CJ31: 0 | CL31: 28660.92 | CO31: 324 | CT31: 0 | CV31: 0 | CY31: 0 | CZ31: =SUM(CM31:CY31) -> 324 | DA31: =CL31-CZ31 -> 28336.92 | DB31: 28933.72 | DC31: 28660.92 | DN31: 57594.64 | DO31: -31750.68 | DP31: 0 | DQ31: 224 | DR31: 324 | EC31: =SUM(DQ31:EB31) -> 548 | ED31: =CP31 -> 0 | EP31: =SUM(ED31:EO31) -> 0
A32: 14 | B32: NIP67065 | C32: TEST 9 | D32: 1449900486868 | E32: Cell Production 12 | F32: Operator | G32: 44952 | I32: 400 | J32: 25 | K32: 10000 | V32: 8 | W32: 400 | X32: 0 | Y32: 0 | Z32: 0 | AA32: 0 | AB32: 8 | AC32: 0 | AD32: 0 | AE32: 400 | AF32: 10800 | AG32: 1300 | AH32: 1890 | AI32: 1215 | AJ32: 1200 | AK32: 1890 | AL32: 0 | AM32: 940.92 | AN32: 0 | AO32: 0 | AP32: 0 | AQ32: 0 | AR32: 500 | AS32: 0 | BU32: 16 | BV32: 1600 | BY32: 6 | BZ32: 900 | CA32: 0 | CB32: 0 | CE32: 0 | CF32: 0 | CG32: 8125 | CH32: 9735.92 | CI32: 0 | CJ32: 0 | CL32: 28660.92 | CO32: 324 | CT32: 0 | CV32: 0 | CY32: 0 | CZ32: =SUM(CM32:CY32) -> 324 | DA32: =CL32-CZ32 -> 28336.92 | DB32: 28933.72 | DC32: 28660.92 | DN32: 57594.64 | DO32: -31750.68 | DP32: 0 | DQ32: 224 | DR32: 324 | EC32: =SUM(DQ32:EB32) -> 548 | ED32: =CP32 -> 0 | EP32: =SUM(ED32:EO32) -> 0
A33: 15 | B33: NIP67066 | C33: TEST 10 | D33: 1449900486869 | E33: Cell Production 13 | F33: Operator | G33: 44953 | I33: 400 | J33: 25 | K33: 10000 | V33: 8 | W33: 400 | X33: 0 | Y33: 0 | Z33: 0 | AA33: 0 | AB33: 8 | AC33: 0 | AD33: 0 | AE33: 400 | AF33: 10800 | AG33: 1300 | AH33: 1890 | AI33: 1215 | AJ33: 1200 | AK33: 1890 | AL33: 0 | AM33: 940.92 | AN33: 0 | AO33: 0 | AP33: 0 | AQ33: 0 | AR33: 500 | AS33: 0 | BU33: 16 | BV33: 1600 | BY33: 6 | BZ33: 900 | CA33: 0 | CB33: 0 | CE33: 0 | CF33: 0 | CG33: 8125 | CH33: 9735.92 | CI33: 0 | CJ33: 0 | CL33: 28660.92 | CO33: 324 | CT33: 0 | CV33: 0 | CY33: 0 | CZ33: =SUM(CM33:CY33) -> 324 | DA33: =CL33-CZ33 -> 28336.92 | DB33: 28933.72 | DC33: 28660.92 | DN33: 57594.64 | DO33: -31750.68 | DP33: 0 | DQ33: 224 | DR33: 324 | EC33: =SUM(DQ33:EB33) -> 548 | ED33: =CP33 -> 0 | EP33: =SUM(ED33:EO33) -> 0
A34: 16 | B34: NIP67067 | C34: TEST 11 | D34: 1449900486870 | E34: Cell Production 14 | F34: Operator | G34: 44954 | I34: 400 | J34: 25 | K34: 10000 | V34: 8 | W34: 400 | X34: 0 | Y34: 0 | Z34: 0 | AA34: 0 | AB34: 8 | AC34: 0 | AD34: 0 | AE34: 400 | AF34: 10800 | AG34: 1300 | AH34: 1890 | AI34: 1215 | AJ34: 1200 | AK34: 1890 | AL34: 0 | AM34: 940.92 | AN34: 0 | AO34: 0 | AP34: 0 | AQ34: 0 | AR34: 500 | AS34: 0 | BU34: 16 | BV34: 1600 | BY34: 6 | BZ34: 900 | CA34: 0 | CB34: 0 | CE34: 0 | CF34: 0 | CG34: 8125 | CH34: 9735.92 | CI34: 0 | CJ34: 0 | CL34: 28660.92 | CO34: 324 | CT34: 0 | CV34: 0 | CY34: 0 | CZ34: =SUM(CM34:CY34) -> 324 | DA34: =CL34-CZ34 -> 28336.92 | DB34: 28933.72 | DC34: 28660.92 | DN34: 57594.64 | DO34: -31750.68 | DP34: 0 | DQ34: 224 | DR34: 324 | EC34: =SUM(DQ34:EB34) -> 548 | ED34: =CP34 -> 0 | EP34: =SUM(ED34:EO34) -> 0
A35: 17 | B35: NIP67068 | C35: TEST 12 | D35: 1449900486871 | E35: Cell Production 15 | F35: Operator | G35: 44955 | I35: 400 | J35: 25 | K35: 10000 | V35: 8 | W35: 400 | X35: 0 | Y35: 0 | Z35: 0 | AA35: 0 | AB35: 8 | AC35: 0 | AD35: 0 | AE35: 400 | AF35: 10800 | AG35: 1300 | AH35: 1890 | AI35: 1215 | AJ35: 1200 | AK35: 1890 | AL35: 0 | AM35: 940.92 | AN35: 0 | AO35: 0 | AP35: 0 | AQ35: 0 | AR35: 500 | AS35: 0 | BU35: 16 | BV35: 1600 | BY35: 6 | BZ35: 900 | CA35: 0 | CB35: 0 | CE35: 0 | CF35: 0 | CG35: 8125 | CH35: 9735.92 | CI35: 0 | CJ35: 0 | CL35: 28660.92 | CO35: 324 | CT35: 0 | CV35: 0 | CY35: 0 | CZ35: =SUM(CM35:CY35) -> 324 | DA35: =CL35-CZ35 -> 28336.92 | DB35: 28933.72 | DC35: 28660.92 | DN35: 57594.64 | DO35: -31750.68 | DP35: 0 | DQ35: 224 | DR35: 324 | EC35: =SUM(DQ35:EB35) -> 548 | ED35: =CP35 -> 0 | EP35: =SUM(ED35:EO35) -> 0
A36: 18 | B36: NIP67069 | C36: TEST 13 | D36: 1449900486872 | E36: Cell Production 16 | F36: Operator | G36: 44956 | I36: 400 | J36: 25 | K36: 10000 | V36: 8 | W36: 400 | X36: 0 | Y36: 0 | Z36: 0 | AA36: 0 | AB36: 8 | AC36: 0 | AD36: 0 | AE36: 400 | AF36: 10800 | AG36: 1300 | AH36: 1890 | AI36: 1215 | AJ36: 1200 | AK36: 1890 | AL36: 0 | AM36: 940.92 | AN36: 0 | AO36: 0 | AP36: 0 | AQ36: 0 | AR36: 500 | AS36: 0 | BU36: 16 | BV36: 1600 | BY36: 6 | BZ36: 900 | CA36: 0 | CB36: 0 | CE36: 0 | CF36: 0 | CG36: 8125 | CH36: 9735.92 | CI36: 0 | CJ36: 0 | CL36: 28660.92 | CO36: 324 | CT36: 0 | CV36: 0 | CY36: 0 | CZ36: =SUM(CM36:CY36) -> 324 | DA36: =CL36-CZ36 -> 28336.92 | DB36: 28933.72 | DC36: 28660.92 | DN36: 57594.64 | DO36: -31750.68 | DP36: 0 | DQ36: 224 | DR36: 324 | EC36: =SUM(DQ36:EB36) -> 548 | ED36: =CP36 -> 0 | EP36: =SUM(ED36:EO36) -> 0
... A118: 100 | B118: NIP67151 | C118: TEST 95 | D118: 1449900486954 | E118: Cell Production 98 | F118: Operator | G118: 45038 | I118: 400 | J118: 25 | K118: 10000 | V118: 8 | W118: 400 | X118: 0 | Y118: 0 | Z118: 0 | AA118: 0 | AB118: 8 | AC118: 0 | AD118: 0 | AE118: 400 | AF118: 10800 | AG118: 1300 | AH118: 1890 | AI118: 1215 | AJ118: 1200 | AK118: 1890 | AL118: 0 | AM118: 940.92 | AN118: 0 | AO118: 0 | AP118: 0 | AQ118: 0 | AR118: 500 | AS118: 0 | BU118: 16 | BV118: 1600 | BY118: 6 | BZ118: 900 | CA118: 0 | CB118: 0 | CE118: 0 | CF118: 0 | CG118: 8125 | CH118: 9735.92 | CI118: 0 | CJ118: 0 | CL118: 28660.92 | CO118: 324 | CT118: 0 | CV118: 0 | CY118: 0 | CZ118: =SUM(CM118:CY118) -> 324 | DA118: =CL118-CZ118 -> 28336.92 | DB118: 28933.72 | DC118: 28660.92 | DN118: 57594.64 | DO118: -31750.68 | DP118: 0 | DQ118: 224 | DR118: 324 | EC118: =SUM(DQ118:EB118) -> 548 | ED118: =CP118 -> 0 | EP118: =SUM(ED118:EO118) -> 0
A119: Total | I119: =SUM(I19:I118) -> 40000 | J119: =SUM(J19:J118) -> 2497 | K119: =SUM(K19:K118) -> 998800 | L119: =SUM(L19:L118) -> 28 | M119: =SUM(M19:M118) -> 0 | N119: =SUM(N19:N118) -> 5 | O119: =SUM(O19:O118) -> 0 | P119: =SUM(P19:P118) -> 2 | ... EP119: =SUM(EP19:EP118) -> 3

Sheet 1
H1: ใบรับเงินเดือน / PAY SLIP
H2: ประจำงวด/ Period: | I2: ='Slip April'!C13 -> Febuary 2025
H3: ประจำสาขา/ Branch: | I3: ='Slip April'!C9 -> Canadian ( Phase 3)
H4: รหัสพนักงาน/ Emp.No : | I4: ='Slip April'!B19 -> NIP67011
H5: แผนก/Dept. | I5: =VLOOKUP(I4,'Slip April'!B:E,4,0) -> Wafer Production
B6: ชื่อสกุล/ Emp. | C6: =VLOOKUP(I4,'Slip April'!B:C,2,0) -> นางสาวฤทัยรัตน์ บุญสม | F6: ตำแหน่ง/Postion: | G6: =VLOOKUP(I4,'Slip April'!B:F,5,0) -> Operator
B8: รายได้ (Income) | F8: รายการหัก (Deduction)
B10: เงินเดือนค่าจ้าง / Wage (K) | C10: =VLOOKUP(I4,'Slip April'!B:I,8,0) -> 400 | D10: บาท/วัน | F10: ภาษีหัก ณ ที่จ่าย / Tax. | G10: =VLOOKUP(I4,'Slip April'!B:CM,90,0) -> 0 | H10: รายได้สะสม (บาท) | I10: =VLOOKUP(I4,'Slip April'!B:DN,117,0) -> 59901.52
B11: วันทำงาน / Working days (J) | C11: =VLOOKUP(I4,'Slip April'!B:J,9,0) -> 26 | D11: วัน | E11: =VLOOKUP(I4,'Slip April'!B:M,10,0) -> 10400 | F11: ประกันสังคม / SSF. | G11: =VLOOKUP(I4,'Slip April'!B:CN,91,0) -> 0
B12: ชั่วโมงการทำงาน / Working hours | C12: =VLOOKUP(I4,'Slip April'!B:L,11,0) -> 8 | D12: ชม. | E12: =VLOOKUP(I4,'Slip April'!B:M,12,0) -> 0 | F12: สงเคราะห์กองทุนลูกจ้าง | G12: =VLOOKUP(I4,'Slip April'!B:CO,92,0) -> 312
B13: วันหยุดประเพณี/ Traditional | C13: =VLOOKUP(I4,'Slip April'!B:N,13,0) -> 2 | D13: วัน | E13: =VLOOKUP(I4,'Slip April'!B:O,14,0) -> 0 | F13: กองทุนสำรองเลี้ยงชีพ | G13: =VLOOKUP(I4,'Slip April'!B:CP,93,0) -> 0
B14: พักร้อน, ป่วย,ลากิจ,ลาคลอด/ Maternity Leave ,AL,SLD,BLD | E14: =VLOOKUP(I4,'Slip April'!B:AE,30,0) -> 0 | F14: กยศ. / Student loan (TSLF) | G14: =VLOOKUP(I4,'Slip April'!B:CR,94,0) -> 0 | H14: ประกันสัมคมสะสม (บาท) | I14: =VLOOKUP(I4,'Slip April'!B:EC,132,0) -> 610
B15: ค่าแรง 75% / Pay 75% of the wage | C15: =VLOOKUP(I4,'Slip April'!B:P,15,0) -> 0 | D15: วัน | E15: =VLOOKUP(I4,'Slip April'!B:Q,16,0) -> 500 | F15: หักบังคับคดี / Enforcement | G15: =VLOOKUP(I4,'Slip April'!B:CS,95,0) -> 0
B16: ค่าแรง 80% / Pay 80% of the wage | C16: =VLOOKUP(I4,'Slip April'!B:R,17,0) -> 5 | D16: วัน | E16: =VLOOKUP(I4,'Slip April'!B:S,18,0) -> 0 | F16: เงินเบิกล่วงหน้า / Advance | G16: =VLOOKUP(I4,'Slip April'!B:CT,96,0) -> 0
B17: ค่าแรง 85% / Pay 85% of the wage | C17: =VLOOKUP(I4,'Slip April'!B:T,19,0) -> 0 | D17: วัน | E17: =VLOOKUP(I4,'Slip April'!B:U,20,0) -> 0 | F17: ชุดยูนิฟอร์ม / Uniform | G17: =VLOOKUP(I4,'Slip April'!B:CU,97,0) -> 0 | H17: ภาษีหัก ณ ที่จ่าย สะสม (บาท) | I17: =VLOOKUP(I4,'Slip April'!B:DP,119,0) -> 0
B18: วันหยุด / Holiday | C18: =VLOOKUP(I4,'Slip April'!B:V,21,0) -> 8 | D18: วัน | E18: =VLOOKUP(I4,'Slip April'!B:W,22,0) -> 400 | F18: คูปอง / Cashless | G18: =VLOOKUP(I4,'Slip April'!B:CV,98,0) -> 0
B19: ค่าล่วงเวลา OT x 1 | C19: =VLOOKUP(I4,'Slip April'!B:BM,64,0) -> 0 | D19: ชม. | E19: =VLOOKUP(I4,'Slip April'!B:BN,65,0) -> 0 | F19: รางวัลบริการประจำปี / Service Year Award | G19: =VLOOKUP(I4,'Slip April'!B:CW,99,0) -> 0
B20: ค่าล่วงเวลา OT x 1.3 | C20: =VLOOKUP(I4,'Slip April'!B:BO,66,0) -> 0 | D20: ชม. | E20: =VLOOKUP(I4,'Slip April'!B:BP,67,0) -> 0 | F20: หยุดงาน,สาย,กลับก่อน / Absent, Late, Leave early | G20: =VLOOKUP(I4,'Slip April'!B:CX,100,0) -> 0 | H20: กองทุนสำรองเลี้ยงชีพสะสม (บาท) | I20: =VLOOKUP(I4,'Slip April'!B:EP,145,0) -> 0
B21: ค่าล่วงเวลา OT x 1.5 | C21: =VLOOKUP(I4,'Slip April'!B:BQ,68,0) -> 0 | D21: ชม. | E21: =VLOOKUP(I4,'Slip April'!B:BR,69,0) -> 0 | F21: อุปกรณ์โรงงาน / PPE | G21: =VLOOKUP(I4,'Slip April'!B:CY,101,0) -> 0
B22: ค่าล่วงเวลา OT x 1.7 | C22: =VLOOKUP(I4,'Slip April'!B:BS,70,0) -> 0 | D22: ชม. | E22: =VLOOKUP(I4,'Slip April'!B:BT,71,0) -> 0 | F22: อื่นๆ / Other | G22: =VLOOKUP(I4,'Slip April'!B:CY,102,0) -> 0
B23: ค่าล่วงเวลา OT x 2 ปกติ / OT x 2 Regular Work Day | C23: =VLOOKUP(I4,'Slip April'!B:BU,72,0) -> 32 | D23: ชม. | E23: =VLOOKUP(I4,'Slip April'!B:BV,73,0) -> 3200
B24: ค่าล่วงเวลา OT x 2.2 | C24: =VLOOKUP(I4,'Slip April'!B:BW,74,0) -> 0 | D24: ชม. | E24: =VLOOKUP(I4,'Slip April'!B:BX,75,0) -> 0
B25: ค่าล่วงเวลา OT x 3 ปกติ / OT x 3 Regular Work Day | C25: =VLOOKUP(I4,'Slip April'!B:BY,76,0) -> 12 | D25: ชม. | E25: =VLOOKUP(I4,'Slip April'!B:BZ,77,0) -> 1800
B26: ค่าล่วงเวลา OT x 2 วันนักขัตฤกษ์ / OT x 2 for Holiday Work | C26: =VLOOKUP(I4,'Slip April'!B:CA,78,0) -> 0 | D26: ชม. | E26: =VLOOKUP(I4,'Slip April'!B:CB,79,0) -> 0
B27: ค่าล่วงเวลา OT x 3 วันนักขัตฤกษ์ / OT x 2 for Holiday Work | C27: =VLOOKUP(I4,'Slip April'!B:BY,76,0) -> 12 | D27: ชม. | E27: =VLOOKUP(I4,'Slip April'!B:BZ,77,0) -> 1800
B28: ค่าล่วงเวลา OT x 3.2 | C28: =VLOOKUP(I4,'Slip April'!B:CE,82,0) -> 0 | D28: ชม. | E28: =VLOOKUP(I4,'Slip April'!B:CF,83,0) -> 0
B29: ค่าอาหาร / Meal Allowance | E29: =VLOOKUP(I4,'Slip April'!B:AG,32,0) -> 1300
B30: ค่าอาหารวันหยุด / Holiday Meal Allowance | E30: =VLOOKUP(I4,'Slip April'!B:AH,33,0) -> 1800
B31: ค่าอาหารล่วงเวลา / OT Meal Allowance | E31: =VLOOKUP(I4,'Slip April'!B:AI,34,0) -> 1200
B32: ค่ากะดึก / Night Shift | E32: =VLOOKUP(I4,'Slip April'!B:AJ,35,0) -> 2900
B33: ค่าอาหารกะดึก / Night Shift Meal Allowance | E33: =VLOOKUP(I4,'Slip April'!B:AK,36,0) -> 1800
B34: ค่ากะเช้า / Day shift | E34: =VLOOKUP(I4,'Slip April'!B:AL,37,0) -> 0
B35: ค่าเดินทาง / Transportation | E35: =VLOOKUP(I4,'Slip April'!B:AM,38,0) -> 0
B36: ค่าเช่าบ้าน / Rental Allowance | E36: =VLOOKUP(I4,'Slip April'!B:AN,39,0) -> 500
B37: ค่าทักษะ / Skill-based | E37: =VLOOKUP(I4,'Slip April'!B:AO,40,0) -> 500
B38: ค่าครองชีพ / Cost of Living Allowance | E38: =VLOOKUP(I4,'Slip April'!B:AP,41,0) -> 3000
B39: ค่าลักษณะงาน / Job description | E39: =VLOOKUP(I4,'Slip April'!B:AQ,42,0) -> 0
B40: ค่าตำแหน่ง / Position allownce | E40: =VLOOKUP(I4,'Slip April'!B:AR,43,0) -> 500
B41: ค่าตรวจพบงานเสีย / Quality award | E41: =VLOOKUP(I4,'Slip April'!B:AS,44,0) -> 1350.04
B42: ค่าความเสี่ยง / Risk allowance | E42: =VLOOKUP(I4,'Slip April'!B:AT,45,0) -> 0
...
